<?xml version="1.0"?>
<sdf version="1.7">
  <model name="pioneer3at">

    <!-- Base Link -->
    <link name="base_link">
      <inertial>
        <mass>21.5</mass>
        <pose>-0.1 0 0.177 0 0 0</pose>
        <inertia>
          <ixx>0.3338</ixx>
          <ixy>0.0</ixy>
          <ixz>0.0</ixz>
          <iyy>0.4783</iyy>
          <iyz>0.0</iyz>
          <izz>0.3338</izz>
        </inertia>
      </inertial>
      <visual name="visual">
        <pose>0 0 0.177 0 0 0</pose>
        <geometry>
          <mesh>
            <uri>model://rf_sensor/meshes/p3at_meshes/chassis.stl</uri>
          </mesh>
        </geometry>
        <material>
          <ambient>0.851 0.0 0.0 1.0</ambient>
        </material>
      </visual>
      <collision name="collision">
        <pose>0 0 0.177 0 0 0</pose>
        <geometry>
          <mesh>
            <uri>model://rf_sensor/meshes/p3at_meshes/chassis.stl</uri>
          </mesh>
        </geometry>
      </collision>
    </link>

    <!-- Top Plate -->
    <link name="top_plate">
      <inertial>
        <mass>0.1</mass>
        <pose>-0.025 0 -0.223 0 0 0</pose>
        <inertia>
          <ixx>1.0</ixx>
          <ixy>0.0</ixy>
          <ixz>0.0</ixz>
          <iyy>1.0</iyy>
          <iyz>0.0</iyz>
          <izz>1.0</izz>
        </inertia>
      </inertial>
      <visual name="visual">
        <pose>0 0 0 0 0 0</pose>
        <geometry>
          <mesh>
            <uri>model://rf_sensor/meshes/p3at_meshes/top.stl</uri>
          </mesh>
        </geometry>
        <material>
          <ambient>0.038 0.038 0.038 1.0</ambient>
        </material>
      </visual>
    </link>
    <joint name="base_top_joint" type="fixed">
      <pose>0.003 0 0.274 0 0 0</pose>
      <parent>base_link</parent>
      <child>top_plate</child>
    </joint>

    <!-- Front Sonar -->
    <link name="front_sonar">
      <inertial>
        <mass>0.1</mass>
        <pose>0 0 0 0 0 0</pose>
        <inertia>
          <ixx>1.0</ixx>
          <ixy>0.0</ixy>
          <ixz>0.0</ixz>
          <iyy>1.0</iyy>
          <iyz>0.0</iyz>
          <izz>1.0</izz>
        </inertia>
      </inertial>
      <visual name="visual">
        <pose>0 0 0 0 0 0</pose>
        <geometry>
          <mesh>
            <uri>model://rf_sensor/meshes/p3at_meshes/front_sonar.stl</uri>
          </mesh>
        </geometry>
        <material>
          <ambient>0.715 0.583 0.210 1.0</ambient>
        </material>
      </visual>
    </link>
    <joint name="base_front_joint" type="fixed">
      <pose>0.193 0 0.25 0 0 0</pose>
      <parent>base_link</parent>
      <child>front_sonar</child>
    </joint>

    <!-- Back Sonar -->
    <link name="back_sonar">
      <inertial>
        <mass>0.1</mass>
        <pose>0 0 0 0 0 0</pose>
        <inertia>
          <ixx>1.0</ixx>
          <ixy>0.0</ixy>
          <ixz>0.0</ixz>
          <iyy>1.0</iyy>
          <iyz>0.0</iyz>
          <izz>1.0</izz>
        </inertia>
      </inertial>
      <visual name="visual">
        <pose>0 0 0 0 0 0</pose>
        <geometry>
          <mesh>
            <uri>model://rf_sensor/meshes/p3at_meshes/back_sonar.stl</uri>
          </mesh>
        </geometry>
        <material>
          <ambient>0.715 0.583 0.210 1.0</ambient>
        </material>
      </visual>
    </link>
    <joint name="base_back_joint" type="fixed">
      <pose>-0.187 0 0.247 0 0 0</pose>
      <parent>base_link</parent>
      <child>back_sonar</child>
    </joint>

    <!-- Drive Side Left -->
    <link name="p3at_front_left_axle">
      <inertial>
        <mass>0.1</mass>
        <pose>0 0 0 0 0 0</pose>
        <inertia>
          <ixx>1.0</ixx>
          <ixy>0.0</ixy>
          <ixz>0.0</ixz>
          <iyy>1.0</iyy>
          <iyz>0.0</iyz>
          <izz>1.0</izz>
        </inertia>
      </inertial>
      <visual name="visual">
        <pose>0 0 0 0 0 0</pose>
        <geometry>
          <mesh>
            <uri>model://rf_sensor/meshes/p3at_meshes/axle.stl</uri>
          </mesh>
        </geometry>
        <material>
          <ambient>0.5 0.5 0.5 1.0</ambient>
        </material>
      </visual>
    </link>
    <joint name="base_front_left_axle_joint" type="fixed">
      <pose>0.135 0.156 0.111 0 0 0</pose>
      <parent>base_link</parent>
      <child>p3at_front_left_axle</child>
    </joint>

    <link name="p3at_front_left_hub">
      <inertial>
        <mass>0.1</mass>
        <pose>0 0 0 0 0 0</pose>
        <inertia>
          <ixx>1.0</ixx>
          <ixy>0.0</ixy>
          <ixz>0.0</ixz>
          <iyy>1.0</iyy>
          <iyz>0.0</iyz>
          <izz>1.0</izz>
        </inertia>
      </inertial>
      <visual name="visual">
        <pose>0 0 0 0 0 0</pose>
        <geometry>
          <mesh>
            <uri>model://rf_sensor/meshes/p3at_meshes/left_hubcap.stl</uri>
          </mesh>
        </geometry>
        <material>
          <ambient>1.0 0.811 0.151 1.0</ambient>
        </material>
      </visual>
    </link>
    <joint name="base_front_left_hub_joint" type="fixed">
      <pose>0 0.041 0 0 0 0</pose>
      <parent>p3at_front_left_axle</parent>
      <child>p3at_front_left_hub</child>
    </joint>

    <link name="p3at_front_left_wheel">
      <inertial>
        <mass>1.2</mass>
        <pose>0 0 0 0 0 0</pose>
        <inertia>
          <ixx>0.012411765597</ixx>
          <ixy>0.0</ixy>
          <ixz>0.0</ixz>
          <iyy>0.015218160428</iyy>
          <iyz>0.0</iyz>
          <izz>0.011763977943</izz>
        </inertia>
      </inertial>
      <visual name="visual">
        <pose>0 0 0 0 0 0</pose>
        <geometry>
          <mesh>
            <uri>model://rf_sensor/meshes/p3at_meshes/wheel.stl</uri>
          </mesh>
        </geometry>
        <material>
          <ambient>0.117 0.117 0.117 1.0</ambient>
        </material>
      </visual>
      <collision name="collision">
        <pose>0 0 0 -1.57079633 0 0</pose>
        <geometry>
          <cylinder>
            <radius>0.111</radius>
            <length>0.075</length>
          </cylinder>
        </geometry>
      </collision>
    </link>
    <joint name="p3at_front_left_wheel_joint" type="continuous">
      <axis>
        <xyz>0 1 0</xyz>
        <limit>
          <effort>100</effort>
          <velocity>100</velocity>
        </limit>
        <dynamics>
          <damping>0.7</damping>
        </dynamics>
      </axis>
      <parent>p3at_front_left_hub</parent>
      <child>p3at_front_left_wheel</child>
    </joint>

    <!-- Repeat for right side and rear wheels/axles/hubs as done for left side -->

    <!-- Plugin for Skid-Steer Drive Controller -->
    <plugin name="skid_steer_drive_controller" filename="libgazebo_ros_skid_steer_drive.so">
      <updateRate>100.0</updateRate>
      <robotNamespace>sim_p3at</robotNamespace>
      <leftFrontJoint>p3at_front_left_wheel_joint</leftFrontJoint>
      <rightFrontJoint>p3at_front_right_wheel_joint</rightFrontJoint>
      <leftRearJoint>p3at_back_left_wheel_joint</leftRearJoint>
      <rightRearJoint>p3at_back_right_wheel_joint</rightRearJoint>
      <wheelSeparation>0.4</wheelSeparation>
      <wheelDiameter>0.215</wheelDiameter>
      <robotBaseFrame>base_link</robotBaseFrame>
      <MaxForce>5.0</MaxForce>
      <torque>200</torque>
      <commandTopic>/cmd_vel</commandTopic>
      <odometryTopic>/odom</odometryTopic>
      <odometryFrame>/odom</odometryFrame>
      <broadcastTF>1</broadcastTF>
    </plugin>

  </model>
</sdf>
